{"uuid": "bb08b0c6-0cf0-4a55-910c-c543d6e35d05", "children": ["3982cdcf-2ceb-4290-ab69-edc033ef7021"], "befores": [{"name": "browser_firefox", "status": "passed", "start": 1683570854191, "stop": 1683570858127}], "afters": [{"name": "browser_firefox::0", "status": "broken", "statusDetails": {"message": "selenium.common.exceptions.InvalidSessionIdException: Message: Tried to run command without establishing a connection\n\n", "trace": "  File \"/Users/evgenijgravdin/tms_aqa/lib/python3.11/site-packages/allure_commons/_allure.py\", line 221, in __call__\n    return self._fixture_function(*args, **kwargs)\n           ^^^^^^^^^^^^^^^^^^^^^^^^^^^^^^^^^^^^^^^\n  File \"/Users/evgenijgravdin/tms_aqa/lib/python3.11/site-packages/_pytest/fixtures.py\", line 918, in _teardown_yield_fixture\n    next(it)\n  File \"/Users/evgenijgravdin/Desktop/tms_aqa_python/conftest.py\", line 47, in browser_firefox\n    driver.close()\n  File \"/Users/evgenijgravdin/tms_aqa/lib/python3.11/site-packages/selenium/webdriver/remote/webdriver.py\", line 551, in close\n    self.execute(Command.CLOSE)\n  File \"/Users/evgenijgravdin/tms_aqa/lib/python3.11/site-packages/selenium/webdriver/remote/webdriver.py\", line 440, in execute\n    self.error_handler.check_response(response)\n  File \"/Users/evgenijgravdin/tms_aqa/lib/python3.11/site-packages/selenium/webdriver/remote/errorhandler.py\", line 245, in check_response\n    raise exception_class(message, screen, stacktrace)\n"}, "start": 1683570862636, "stop": 1683570862645}], "start": 1683570854191, "stop": 1683570862645}